const API = {
  async getLastWorkout() {
    let res;
    try {
      res = await fetch("/api/workouts");
    } catch (err) {
      console.log(err)
      // catch this and just log without blowing up?  No.  I'm rethrowing
      throw err;
    }
    const json = await res.json();

    return json[json.length - 1];
  },
  async addExercise(data) {
    const id = location.search.split("=")[1];

    if(!id) {
      console.error("you're adding an exercise to a location without an id after the =.  That is, you're not on a valid workout page")
    }

    const res = await fetch("/api/workouts/" + id, {
      method: "PUT",
      headers: { "Content-Type": "application/json" },
      body: JSON.stringify(data)
    });

    const json = await res.json();

    return json;
  },
  async createWorkout(data = {}) {
    const res = await fetch("/api/workouts", {
      method: "POST",
      body: JSON.stringify(data),
      headers: { "Content-Type": "application/json" }
    });

    const json = await res.json();

    return json;
  },

  async getWorkoutsInRange() {
    const res = await fetch(`/api/workouts/range`);
    const json = await res.json();

    return json;
  },
};
